Workbook

Sheet Тарифы
A1: Товар | B1: Объем Л | C1: Тариф, рубли | D1: межкласстерный коэффицент | E1: Дальний Восток | F1: Калининград | G1: Санкт-Петербург и СЗО | H1: Воронеж | I1: Москва, МО и Дальние регионы | J1: Уфа | K1: Казань | L1: Самара | M1: Красноярск | N1: Тюмень | O1: Невинномысск | P1: Махачкала | Q1: Саратов | R1: Ярославль | S1: Краснодар | T1: Екатеринбург | U1: Новосибирск | V1: Омск | W1: Оренбург | X1: Пермь | Y1: Ростов | Z1: Тверь | AB1: Объём товара, литры | AC1: Тариф, рубли
A2: ШБС 01-17 | B2: 348 | C2: 1859 | E2: =2.4*C2 -> 4461.6 | F2: =1.7*C2 -> 3160.3 | G2: =1.5*C2 -> 2788.5 | H2: =1.4*C2 -> 2602.6 | I2: =1.3*C2 -> 2416.7 | J2: =1.2*C2 -> 2230.8 | K2: =1*C2 -> 1859 | L2: =1.1*C2 -> 2044.9 | M2: =1.7*C2 -> 3160.3 | N2: =1.7*C2 -> 3160.3 | O2: =1.6*C2 -> 2974.4 | P2: =1.6*C2 -> 2974.4 | Q2: =1.1*C2 -> 2044.9 | R2: =1.3*C2 -> 2416.7 | S2: =1.6*C2 -> 2974.4 | T2: =1.3*C2 -> 2416.7 | U2: =1.7*C2 -> 3160.3 | V2: =1.7*C2 -> 3160.3 | W2: =1.2*C2 -> 2230.8 | X2: =1.3*C2 -> 2416.7 | Y2: =1.6*C2 -> 2974.4 | Z2: =1.3*C2 -> 2416.7 | AB2: 0 - 0.2 | AC2: 50
A3: ШБС 02-17 | B3: 348 | C3: 1859 | E3: =2.4*C3 -> 4461.6 | F3: =1.7*C3 -> 3160.3 | G3: =1.5*C3 -> 2788.5 | H3: =1.4*C3 -> 2602.6 | I3: =1.3*C3 -> 2416.7 | J3: =1.2*C3 -> 2230.8 | K3: =1*C3 -> 1859 | L3: =1.1*C3 -> 2044.9 | M3: =1.7*C3 -> 3160.3 | N3: =1.7*C3 -> 3160.3 | O3: =1.6*C3 -> 2974.4 | P3: =1.6*C3 -> 2974.4 | Q3: =1.1*C3 -> 2044.9 | R3: =1.3*C3 -> 2416.7 | S3: =1.6*C3 -> 2974.4 | T3: =1.3*C3 -> 2416.7 | U3: =1.7*C3 -> 3160.3 | V3: =1.7*C3 -> 3160.3 | W3: =1.2*C3 -> 2230.8 | X3: =1.3*C3 -> 2416.7 | Y3: =1.6*C3 -> 2974.4 | Z3: =1.3*C3 -> 2416.7 | AB3: 0.21 - 0.4 | AC3: 55
A4: СМ 30 | B4: 37 | C4: 263 | E4: =2.4*C4 -> 631.2 | F4: =1.7*C4 -> 447.1 | G4: =1.5*C4 -> 394.5 | H4: =1.4*C4 -> 368.2 | I4: =1.3*C4 -> 341.9 | J4: =1.2*C4 -> 315.6 | K4: =1*C4 -> 263 | L4: =1.1*C4 -> 289.3 | M4: =1.7*C4 -> 447.1 | N4: =1.7*C4 -> 447.1 | O4: =1.6*C4 -> 420.8 | P4: =1.6*C4 -> 420.8 | Q4: =1.1*C4 -> 289.3 | R4: =1.3*C4 -> 341.9 | S4: =1.6*C4 -> 420.8 | T4: =1.3*C4 -> 341.9 | U4: =1.7*C4 -> 447.1 | V4: =1.7*C4 -> 447.1 | W4: =1.2*C4 -> 315.6 | X4: =1.3*C4 -> 341.9 | Y4: =1.6*C4 -> 420.8 | Z4: =1.3*C4 -> 341.9 | AB4: 0.41 - 0.6 | AC4: 58
A5: СМ 30-Э | B5: 37 | C5: 263 | E5: =2.4*C5 -> 631.2 | F5: =1.7*C5 -> 447.1 | G5: =1.5*C5 -> 394.5 | H5: =1.4*C5 -> 368.2 | I5: =1.3*C5 -> 341.9 | J5: =1.2*C5 -> 315.6 | K5: =1*C5 -> 263 | L5: =1.1*C5 -> 289.3 | M5: =1.7*C5 -> 447.1 | N5: =1.7*C5 -> 447.1 | O5: =1.6*C5 -> 420.8 | P5: =1.6*C5 -> 420.8 | Q5: =1.1*C5 -> 289.3 | R5: =1.3*C5 -> 341.9 | S5: =1.6*C5 -> 420.8 | T5: =1.3*C5 -> 341.9 | U5: =1.7*C5 -> 447.1 | V5: =1.7*C5 -> 447.1 | W5: =1.2*C5 -> 315.6 | X5: =1.3*C5 -> 341.9 | Y5: =1.6*C5 -> 420.8 | Z5: =1.3*C5 -> 341.9 | AB5: 0.61 - 0.8 | AC5: 61
A6: СМ 50 | B6: 59 | C6: 334 | E6: =2.4*C6 -> 801.6 | F6: =1.7*C6 -> 567.8 | G6: =1.5*C6 -> 501 | H6: =1.4*C6 -> 467.6 | I6: =1.3*C6 -> 434.2 | J6: =1.2*C6 -> 400.8 | K6: =1*C6 -> 334 | L6: =1.1*C6 -> 367.4 | M6: =1.7*C6 -> 567.8 | N6: =1.7*C6 -> 567.8 | O6: =1.6*C6 -> 534.4 | P6: =1.6*C6 -> 534.4 | Q6: =1.1*C6 -> 367.4 | R6: =1.3*C6 -> 434.2 | S6: =1.6*C6 -> 534.4 | T6: =1.3*C6 -> 434.2 | U6: =1.7*C6 -> 567.8 | V6: =1.7*C6 -> 567.8 | W6: =1.2*C6 -> 400.8 | X6: =1.3*C6 -> 434.2 | Y6: =1.6*C6 -> 534.4 | Z6: =1.3*C6 -> 434.2 | AB6: 0.81 - 1 | AC6: 63
A7: СМ 50-Э | B7: 59 | C7: 334 | E7: =2.4*C7 -> 801.6 | F7: =1.7*C7 -> 567.8 | G7: =1.5*C7 -> 501 | H7: =1.4*C7 -> 467.6 | I7: =1.3*C7 -> 434.2 | J7: =1.2*C7 -> 400.8 | K7: =1*C7 -> 334 | L7: =1.1*C7 -> 367.4 | M7: =1.7*C7 -> 567.8 | N7: =1.7*C7 -> 567.8 | O7: =1.6*C7 -> 534.4 | P7: =1.6*C7 -> 534.4 | Q7: =1.1*C7 -> 367.4 | R7: =1.3*C7 -> 434.2 | S7: =1.6*C7 -> 534.4 | T7: =1.3*C7 -> 434.2 | U7: =1.7*C7 -> 567.8 | V7: =1.7*C7 -> 567.8 | W7: =1.2*C7 -> 400.8 | X7: =1.3*C7 -> 434.2 | Y7: =1.6*C7 -> 534.4 | Z7: =1.3*C7 -> 434.2 | AB7: 1.01 - 1.25 | AC7: 71
A8: СМ 25 | B8: 24 | C8: 210 | E8: =2.4*C8 -> 504 | F8: =1.7*C8 -> 357 | G8: =1.5*C8 -> 315 | H8: =1.4*C8 -> 294 | I8: =1.3*C8 -> 273 | J8: =1.2*C8 -> 252 | K8: =1*C8 -> 210 | L8: =1.1*C8 -> 231 | M8: =1.7*C8 -> 357 | N8: =1.7*C8 -> 357 | O8: =1.6*C8 -> 336 | P8: =1.6*C8 -> 336 | Q8: =1.1*C8 -> 231 | R8: =1.3*C8 -> 273 | S8: =1.6*C8 -> 336 | T8: =1.3*C8 -> 273 | U8: =1.7*C8 -> 357 | V8: =1.7*C8 -> 357 | W8: =1.2*C8 -> 252 | X8: =1.3*C8 -> 273 | Y8: =1.6*C8 -> 336 | Z8: =1.3*C8 -> 273 | AB8: 1.26 - 1.5 | AC8: 74
A9: СМ 25-Э | B9: 24 | C9: 210 | E9: =2.4*C9 -> 504 | F9: =1.7*C9 -> 357 | G9: =1.5*C9 -> 315 | H9: =1.4*C9 -> 294 | I9: =1.3*C9 -> 273 | J9: =1.2*C9 -> 252 | K9: =1*C9 -> 210 | L9: =1.1*C9 -> 231 | M9: =1.7*C9 -> 357 | N9: =1.7*C9 -> 357 | O9: =1.6*C9 -> 336 | P9: =1.6*C9 -> 336 | Q9: =1.1*C9 -> 231 | R9: =1.3*C9 -> 273 | S9: =1.6*C9 -> 336 | T9: =1.3*C9 -> 273 | U9: =1.7*C9 -> 357 | V9: =1.7*C9 -> 357 | W9: =1.2*C9 -> 252 | X9: =1.3*C9 -> 273 | Y9: =1.6*C9 -> 336 | Z9: =1.3*C9 -> 273 | AB9: 1.51 - 1.75 | AC9: 77
A10: СМ 23-Э | B10: 34 | C10: 215 | E10: =2.4*C10 -> 516 | F10: =1.7*C10 -> 365.5 | G10: =1.5*C10 -> 322.5 | H10: =1.4*C10 -> 301 | I10: =1.3*C10 -> 279.5 | J10: =1.2*C10 -> 258 | K10: =1*C10 -> 215 | L10: =1.1*C10 -> 236.5 | M10: =1.7*C10 -> 365.5 | N10: =1.7*C10 -> 365.5 | O10: =1.6*C10 -> 344 | P10: =1.6*C10 -> 344 | Q10: =1.1*C10 -> 236.5 | R10: =1.3*C10 -> 279.5 | S10: =1.6*C10 -> 344 | T10: =1.3*C10 -> 279.5 | U10: =1.7*C10 -> 365.5 | V10: =1.7*C10 -> 365.5 | W10: =1.2*C10 -> 258 | X10: =1.3*C10 -> 279.5 | Y10: =1.6*C10 -> 344 | Z10: =1.3*C10 -> 279.5 | AB10: 1.76 - 2 | AC10: 81
A11: СМ 23 | B11: 35 | C11: 263 | E11: =2.4*C11 -> 631.2 | F11: =1.7*C11 -> 447.1 | G11: =1.5*C11 -> 394.5 | H11: =1.4*C11 -> 368.2 | I11: =1.3*C11 -> 341.9 | J11: =1.2*C11 -> 315.6 | K11: =1*C11 -> 263 | L11: =1.1*C11 -> 289.3 | M11: =1.7*C11 -> 447.1 | N11: =1.7*C11 -> 447.1 | O11: =1.6*C11 -> 420.8 | P11: =1.6*C11 -> 420.8 | Q11: =1.1*C11 -> 289.3 | R11: =1.3*C11 -> 341.9 | S11: =1.6*C11 -> 420.8 | T11: =1.3*C11 -> 341.9 | U11: =1.7*C11 -> 447.1 | V11: =1.7*C11 -> 447.1 | W11: =1.2*C11 -> 315.6 | X11: =1.3*C11 -> 341.9 | Y11: =1.6*C11 -> 420.8 | Z11: =1.3*C11 -> 341.9 | AB11: 2.01 - 3 | AC11: 81
A12: СМ 20 | B12: 14 | C12: 170 | E12: =2.4*C12 -> 408 | F12: =1.7*C12 -> 289 | G12: =1.5*C12 -> 255 | H12: =1.4*C12 -> 238 | I12: =1.3*C12 -> 221 | J12: =1.2*C12 -> 204 | K12: =1*C12 -> 170 | L12: =1.1*C12 -> 187 | M12: =1.7*C12 -> 289 | N12: =1.7*C12 -> 289 | O12: =1.6*C12 -> 272 | P12: =1.6*C12 -> 272 | Q12: =1.1*C12 -> 187 | R12: =1.3*C12 -> 221 | S12: =1.6*C12 -> 272 | T12: =1.3*C12 -> 221 | U12: =1.7*C12 -> 289 | V12: =1.7*C12 -> 289 | W12: =1.2*C12 -> 204 | X12: =1.3*C12 -> 221 | Y12: =1.6*C12 -> 272 | Z12: =1.3*C12 -> 221 | AB12: 3.01 - 4 | AC12: 87
A13: СМ 20-Э | B13: 14 | C13: 170 | E13: =2.4*C13 -> 408 | F13: =1.7*C13 -> 289 | G13: =1.5*C13 -> 255 | H13: =1.4*C13 -> 238 | I13: =1.3*C13 -> 221 | J13: =1.2*C13 -> 204 | K13: =1*C13 -> 170 | L13: =1.1*C13 -> 187 | M13: =1.7*C13 -> 289 | N13: =1.7*C13 -> 289 | O13: =1.6*C13 -> 272 | P13: =1.6*C13 -> 272 | Q13: =1.1*C13 -> 187 | R13: =1.3*C13 -> 221 | S13: =1.6*C13 -> 272 | T13: =1.3*C13 -> 221 | U13: =1.7*C13 -> 289 | V13: =1.7*C13 -> 289 | W13: =1.2*C13 -> 204 | X13: =1.3*C13 -> 221 | Y13: =1.6*C13 -> 272 | Z13: =1.3*C13 -> 221 | AB13: 4.01 - 5 | AC13: 99
... A27: 200*100*40 4п | B27: 44 | C27: 269 | E27: =2.4*C27 -> 645.6 | F27: =1.7*C27 -> 457.3 | G27: =1.5*C27 -> 403.5 | H27: =1.4*C27 -> 376.6 | I27: =1.3*C27 -> 349.7 | J27: =1.2*C27 -> 322.8 | K27: =1*C27 -> 269 | L27: =1.1*C27 -> 295.9 | M27: =1.7*C27 -> 457.3 | N27: =1.7*C27 -> 457.3 | O27: =1.6*C27 -> 430.4 | P27: =1.6*C27 -> 430.4 | Q27: =1.1*C27 -> 295.9 | R27: =1.3*C27 -> 349.7 | S27: =1.6*C27 -> 430.4 | T27: =1.3*C27 -> 349.7 | U27: =1.7*C27 -> 457.3 | V27: =1.7*C27 -> 457.3 | W27: =1.2*C27 -> 322.8 | X27: =1.3*C27 -> 349.7 | Y27: =1.6*C27 -> 430.4 | Z27: =1.3*C27 -> 349.7 | AB27: 25.01 - 30 | AC27: 210
AB28: 30.01 - 35 | AC28: 215
AB29: 35.01 - 40 | AC29: 263
A30: Объём отгрузки* | B30: Тариф на литр отгрузки | D30: Тип точки отгрузки | E30: Тариф за отправление | G30: ДОСТАВКА ДО ПВЗ | I30: Выдача товара | K30: Обработка возврата | M30: Обратная логистика | O30: если коэф меньше 1,7 | P30: если коэф больше 1,6 | AB30: 40.01 - 45 | AC30: 269
A31: до 1000 л | B31: 1,9 ₽ | D31: ПВЗ/ППЗ | E31: 30 ₽ | G31: до 25р | I31: от 5% до 10% от цены товара, но не превышает 250 ₽. | K31: 15р за товар | M31: Тариф на обратную логистику равен тарифу на логистику, но без учёта межкластерного коэффициента. | AB31: 45.01 - 50 | AC31: 283
A32: от 1000 до 4000 л | B32: 1,7 ₽ | D32: СЦ | E32: 20 ₽ | AB32: 50.01 - 60 | AC32: 334
A33: от 4000 до 16 000 л | B33: 1,5 ₽ | AB33: 60.01 - 70 | AC33: 364
A34: более 16 000 л | B34: 1,3 ₽ | E34: Комиссия за отгрузку+отправление в сц 20р+ доставка до пвз 25р+выдача товара 250р+обработка возврата 15р+тариф на обратную логистику+межкласстерный коэффицент+вознаграждение МП | AB34: 70.01 - 80 | AC34: 443
AB35: 80.01 - 90 | AC35: 443
AB36: 90.01 - 100 | AC36: 455
AB37: 100.01 - 125 | AC37: 535
AB38: 125.01 - 150 | AC38: 659
AB39: 150.01 - 175 | AC39: 747
AB40: 175.01 - 190 | AC40: 905
AB41: 190.01 - 191 | AC41: 911
AB42: 191.01 - 192 | AC42: 917
AB43: 192.01 - 193 | AC43: 923
AB44: 193.01 - 194 | AC44: 929
AB45: 194.01 - 195 | AC45: 935
AB46: 195.01 - 196 | AC46: 941
... AB850: 999.01 - 1000 | AC850: 5765

Sheet Калькуляция
A1: Наименование | B1: SKU | C1: Размер | D1: Фактическая себестоимость | E1: Цена + НДС ближ | F1: Цена + НДС сред | G1: Цена + НДС дальн | H1: Общая комиссия на OZON за ед. товара FBS (1,5% - эквайринг, обработка отправления - 30 руб, доставка до места выдачи - 25 руб+логистика+вознаграждение OZON) БЛИЖ | I1: Общая комиссия на OZON за ед. товара FBS (1,5% - эквайринг, обработка отправления - 30 руб, доставка до места выдачи - 25 руб+логистика+вознаграждение OZON) СРЕД | J1: Общая комиссия на OZON за ед. товара FBS (1,5% - эквайринг, обработка отправления - 30 руб, доставка до места выдачи - 25 руб+логистика+вознаграждение OZON) ДАЛЬН | K1: Чистая цена после вычета комиссий БЛИЖ | L1: Чистая цена после вычета комиссий СРЕД | M1: Чистая цена после вычета комиссий ДАЛЬН | N1: Прибыль БЛИЖ | O1: Прибыль СРЕД | P1: Прибыль ДАЛЬН | Q1: Рекоменндованная цена ближ | R1: Рекоменндованная цена сред | S1: Рекоменндованная цена дальн | T1: Желаемая рент | U1: Цена от 01.04.2026 | V1: Разница с нынешними БЛИЖ | W1: Разница с нынешними СРЕД | X1: Разница с нынешними ДАЛЬН
A2: Аптечка АМУ-1 | B2: 907247263 | C2: 385х300х160 | D2: ='[1]АМУ-1'!F43/1.07 -> 535.30474 | E2: 2620.3758 | F2: 2859.3716 | G2: 3150.6549 | H2: =('Общая комиссия'!G2+'Общая комиссия'!J2+'Общая комиссия'!K2+'Общая комиссия'!L2+'Общая комиссия'!M2+'Общая комиссия'!N2+'Общая комиссия'!Q2)*1.22 -> 1925.6713 | I2: =('Общая комиссия'!H2+'Общая комиссия'!J2+'Общая комиссия'!K2+'Общая комиссия'!L2+'Общая комиссия'!M2+'Общая комиссия'!O2+'Общая комиссия'!Q2)*1.22 -> 2164.8013 | J2: =('Общая комиссия'!I2+'Общая комиссия'!J2+'Общая комиссия'!K2+'Общая комиссия'!L2+'Общая комиссия'!M2+'Общая комиссия'!P2+'Общая комиссия'!Q2)*1.22 -> 2618.5981 | K2: =E2-H2 -> 694.70447 | L2: =F2-I2 -> 694.57036 | M2: =G2-J2 -> 532.05677 | N2: =K2/D2-1 -> 0.29777381 | O2: =L2/D2-1 -> 0.29752328 | P2: =M2/D2-1 -> -0.0060675168 | Q2: =D2*($T$2/100+1)+H2 -> 2621.5675 | R2: =D2*($T$2/100+1)+I2 -> 2860.6974 | S2: =D2*($T$2/100+1)+J2 -> 3314.4943 | T2: 30 | U2: 3919 | V2: =U2-E2 -> 1298.6242 | W2: =U2-F2 -> 1059.6284 | X2: =U2-G2 -> 768.3451
A3: Ключница К-148 | B3: 629880865 | C3: 430х343х70 | D3: ='[1]К-148'!F46/1.07 -> 1529.4786 | E3: 5069.8174 | F3: 5175.958 | G3: 5021.8939 | H3: =('Общая комиссия'!G3+'Общая комиссия'!J3+'Общая комиссия'!K3+'Общая комиссия'!L3+'Общая комиссия'!M3+'Общая комиссия'!N3+'Общая комиссия'!Q3)*1.22 -> 3082.964 | I3: =('Общая комиссия'!H3+'Общая комиссия'!J3+'Общая комиссия'!K3+'Общая комиссия'!L3+'Общая комиссия'!M3+'Общая комиссия'!O3+'Общая комиссия'!Q3)*1.22 -> 3189.1534 | J3: =('Общая комиссия'!I3+'Общая комиссия'!J3+'Общая комиссия'!K3+'Общая комиссия'!L3+'Общая комиссия'!M3+'Общая комиссия'!P3+'Общая комиссия'!Q3)*1.22 -> 3300.5423 | K3: =E3-H3 -> 1986.8534 | L3: =F3-I3 -> 1986.8047 | M3: =G3-J3 -> 1721.3516 | N3: =K3/D3-1 -> 0.29903967 | O3: =L3/D3-1 -> 0.29900781 | P3: =M3/D3-1 -> 0.12544992 | Q3: =D3*($T$2/100+1)+H3 -> 5071.2862 | R3: =D3*($T$2/100+1)+I3 -> 5177.4756 | S3: =D3*($T$2/100+1)+J3 -> 5288.8645 | U3: 5853.1888 | V3: =U3-E3 -> 783.3714 | W3: =U3-F3 -> 677.23076 | X3: =U3-G3 -> 831.29488
A4: Ключница К-20 | B4: 633898130 | C4: 275x195x70 | D4: ='[1]К-20'!F41/1.07 -> 302.76908 | E4: 1330.7173 | F4: 1422.1162 | G4: 1473.6112 | H4: =('Общая комиссия'!G4+'Общая комиссия'!J4+'Общая комиссия'!K4+'Общая комиссия'!L4+'Общая комиссия'!M4+'Общая комиссия'!N4+'Общая комиссия'!Q4)*1.22 -> 937.58904 | I4: =('Общая комиссия'!H4+'Общая комиссия'!J4+'Общая комиссия'!K4+'Общая комиссия'!L4+'Общая комиссия'!M4+'Общая комиссия'!O4+'Общая комиссия'!Q4)*1.22 -> 1029.0299 | J4: =('Общая комиссия'!I4+'Общая комиссия'!J4+'Общая комиссия'!K4+'Общая комиссия'!L4+'Общая комиссия'!M4+'Общая комиссия'!P4+'Общая комиссия'!Q4)*1.22 -> 1158.4632 | K4: =E4-H4 -> 393.12825 | L4: =F4-I4 -> 393.08628 | M4: =G4-J4 -> 315.14802 | N4: =K4/D4-1 -> 0.29844252 | O4: =L4/D4-1 -> 0.29830389 | P4: =M4/D4-1 -> 0.040885748 | Q4: =D4*($T$2/100+1)+H4 -> 1331.1889 | R4: =D4*($T$2/100+1)+I4 -> 1422.6297 | S4: =D4*($T$2/100+1)+J4 -> 1552.063 | U4: 1511.9205 | V4: =U4-E4 -> 181.20324 | W4: =U4-F4 -> 89.804356 | X4: =U4-G4 -> 38.309311
A5: Ключница К-40 | B5: 629825193 | C5: 430х343х70 | D5: ='[1]К-40'!F44/1.07 -> 716.9912 | E5: 2790.7106 | F5: 2896.8512 | G5: 2970.6978 | H5: =('Общая комиссия'!G5+'Общая комиссия'!J5+'Общая комиссия'!K5+'Общая комиссия'!L5+'Общая комиссия'!M5+'Общая комиссия'!N5+'Общая комиссия'!Q5)*1.22 -> 1859.5394 | I5: =('Общая комиссия'!H5+'Общая комиссия'!J5+'Общая комиссия'!K5+'Общая комиссия'!L5+'Общая комиссия'!M5+'Общая комиссия'!O5+'Общая комиссия'!Q5)*1.22 -> 1965.7288 | J5: =('Общая комиссия'!I5+'Общая комиссия'!J5+'Общая комиссия'!K5+'Общая комиссия'!L5+'Общая комиссия'!M5+'Общая комиссия'!P5+'Общая комиссия'!Q5)*1.22 -> 2196.6797 | K5: =E5-H5 -> 931.17115 | L5: =F5-I5 -> 931.12241 | M5: =G5-J5 -> 774.01806 | N5: =K5/D5-1 -> 0.29872048 | O5: =L5/D5-1 -> 0.2986525 | P5: =M5/D5-1 -> 0.079536353 | Q5: =D5*($T$2/100+1)+H5 -> 2791.628 | R5: =D5*($T$2/100+1)+I5 -> 2897.8174 | S5: =D5*($T$2/100+1)+J5 -> 3128.7683 | U5: 3514.0143 | V5: =U5-E5 -> 723.30367 | W5: =U5-F5 -> 617.16304 | X5: =U5-G5 -> 543.31648
A6: Ключница К-60 | B6: 629844259 | C6: 430х343х70 | D6: ='[1]К-60'!F44/1.07 -> 850.1986 | E6: 3196.5966 | F6: 3287.9955 | G6: 3346.6093 | H6: =('Общая комиссия'!G6+'Общая комиссия'!J6+'Общая комиссия'!K6+'Общая комиссия'!L6+'Общая комиссия'!M6+'Общая комиссия'!N6+'Общая комиссия'!Q6)*1.22 -> 2092.3641 | I6: =('Общая комиссия'!H6+'Общая комиссия'!J6+'Общая комиссия'!K6+'Общая комиссия'!L6+'Общая комиссия'!M6+'Общая комиссия'!O6+'Общая комиссия'!Q6)*1.22 -> 2183.8049 | J6: =('Общая комиссия'!I6+'Общая комиссия'!J6+'Общая комиссия'!K6+'Общая комиссия'!L6+'Общая комиссия'!M6+'Общая комиссия'!P6+'Общая комиссия'!Q6)*1.22 -> 2419.3917 | K6: =E6-H6 -> 1104.2326 | L6: =F6-I6 -> 1104.1906 | M6: =G6-J6 -> 927.21758 | N6: =K6/D6-1 -> 0.29879367 | O6: =L6/D6-1 -> 0.2987443 | P6: =M6/D6-1 -> 0.090589395 | Q6: =D6*($T$2/100+1)+H6 -> 3197.6223 | R6: =D6*($T$2/100+1)+I6 -> 3289.0631 | S6: =D6*($T$2/100+1)+J6 -> 3524.6499 | U6: 3980.4151 | V6: =U6-E6 -> 783.81842 | W6: =U6-F6 -> 692.41953 | X6: =U6-G6 -> 633.80576
A7: Почтовый ящик ЯП-04 с замками | B7: 632063202 | C7: 474х377х190 | D7: ='[1]ЯП-04 NEW'!F39/1.07 -> 1032.8655 | E7: 4755.0731 | F7: 5037.7341 | G7: 5571.1092 | H7: =('Общая комиссия'!G7+'Общая комиссия'!J7+'Общая комиссия'!K7+'Общая комиссия'!L7+'Общая комиссия'!M7+'Общая комиссия'!N7+'Общая комиссия'!Q7)*1.22 -> 3414.882 | I7: =('Общая комиссия'!H7+'Общая комиссия'!J7+'Общая комиссия'!K7+'Общая комиссия'!L7+'Общая комиссия'!M7+'Общая комиссия'!O7+'Общая комиссия'!Q7)*1.22 -> 3697.7359 | J7: =('Общая комиссия'!I7+'Общая комиссия'!J7+'Общая комиссия'!K7+'Общая комиссия'!L7+'Общая комиссия'!M7+'Общая комиссия'!P7+'Общая комиссия'!Q7)*1.22 -> 4511.0719 | K7: =E7-H7 -> 1340.1911 | L7: =F7-I7 -> 1339.9982 | M7: =G7-J7 -> 1060.0374 | N7: =K7/D7-1 -> 0.29754653 | O7: =L7/D7-1 -> 0.29735979 | P7: =M7/D7-1 -> 0.026307249 | Q7: =D7*($T$2/100+1)+H7 -> 4757.6072 | R7: =D7*($T$2/100+1)+I7 -> 5040.4611 | S7: =D7*($T$2/100+1)+J7 -> 5853.797 | U7: 6828.5089 | V7: =U7-E7 -> 2073.4358 | W7: =U7-F7 -> 1790.7748 | X7: =U7-G7 -> 1257.3997
A8: Почтовый ящик ЯП-05 с замками | B8: 631939684 | C8: 559х377х190 | D8: ='[1]ЯП-05 NEW'!F39/1.07 -> 1219.2204 | E8: 5538.2857 | F8: 5814.7344 | G8: 6357.0715 | H8: =('Общая комиссия'!G8+'Общая комиссия'!J8+'Общая комиссия'!K8+'Общая комиссия'!L8+'Общая комиссия'!M8+'Общая комиссия'!N8+'Общая комиссия'!Q8)*1.22 -> 3956.2299 | I8: =('Общая комиссия'!H8+'Общая комиссия'!J8+'Общая комиссия'!K8+'Общая комиссия'!L8+'Общая комиссия'!M8+'Общая комиссия'!O8+'Общая комиссия'!Q8)*1.22 -> 4232.8672 | J8: =('Общая комиссия'!I8+'Общая комиссия'!J8+'Общая комиссия'!K8+'Общая комиссия'!L8+'Общая комиссия'!M8+'Общая комиссия'!P8+'Общая комиссия'!Q8)*1.22 -> 5094.6163 | K8: =E8-H8 -> 1582.0557 | L8: =F8-I8 -> 1581.8671 | M8: =G8-J8 -> 1262.4551 | N8: =K8/D8-1 -> 0.29759621 | O8: =L8/D8-1 -> 0.29744149 | P8: =M8/D8-1 -> 0.035460987 | Q8: =D8*($T$2/100+1)+H8 -> 5541.2164 | R8: =D8*($T$2/100+1)+I8 -> 5817.8537 | S8: =D8*($T$2/100+1)+J8 -> 6679.6028 | U8: 7997.6248 | V8: =U8-E8 -> 2459.3392 | W8: =U8-F8 -> 2182.8905 | X8: =U8-G8 -> 1640.5534
A9: Почтовый ящик ЯП-06 с замками | B9: 631949713 | C9: 643х377х190 | D9: ='[1]ЯП-06 NEW'!F39/1.07 -> 1270.36 | E9: 6006.4496 | F9: 6369.871 | G9: 7108.2938 | H9: =('Общая комиссия'!G9+'Общая комиссия'!J9+'Общая комиссия'!K9+'Общая комиссия'!L9+'Общая комиссия'!M9+'Общая комиссия'!N9+'Общая комиссия'!Q9)*1.22 -> 4358.2265 | I9: =('Общая комиссия'!H9+'Общая комиссия'!J9+'Общая комиссия'!K9+'Общая комиссия'!L9+'Общая комиссия'!M9+'Общая комиссия'!O9+'Общая комиссия'!Q9)*1.22 -> 4721.8958 | J9: =('Общая комиссия'!I9+'Общая комиссия'!J9+'Общая комиссия'!K9+'Общая комиссия'!L9+'Общая комиссия'!M9+'Общая комиссия'!P9+'Общая комиссия'!Q9)*1.22 -> 5817.566 | K9: =E9-H9 -> 1648.2231 | L9: =F9-I9 -> 1647.9751 | M9: =G9-J9 -> 1290.7278 | N9: =K9/D9-1 -> 0.2974457 | O9: =L9/D9-1 -> 0.29725049 | P9: =M9/D9-1 -> 0.016033108 | Q9: =D9*($T$2/100+1)+H9 -> 6009.6945 | R9: =D9*($T$2/100+1)+I9 -> 6373.3638 | S9: =D9*($T$2/100+1)+J9 -> 7469.034 | U9: 8582.266 | V9: =U9-E9 -> 2575.8164 | W9: =U9-F9 -> 2212.3951 | X9: =U9-G9 -> 1473.9723
A10: Почтовый ящик ЯП-08 с замками | B10: 631946118 | C10: 812х377х190 | D10: ='[1]ЯП-08 NEW'!F39/1.07 -> 1776.5508 | E10: 7836.3059 | F10: 8561.5279 | G10: 9720.9657 | H10: =('Общая комиссия'!G10+'Общая комиссия'!J10+'Общая комиссия'!K10+'Общая комиссия'!L10+'Общая комиссия'!M10+'Общая комиссия'!N10+'Общая комиссия'!Q10)*1.22 -> 5530.8709 | I10: =('Общая комиссия'!H10+'Общая комиссия'!J10+'Общая комиссия'!K10+'Общая комиссия'!L10+'Общая комиссия'!M10+'Общая комиссия'!O10+'Общая комиссия'!Q10)*1.22 -> 6256.5877 | J10: =('Общая комиссия'!I10+'Общая комиссия'!J10+'Общая комиссия'!K10+'Общая комиссия'!L10+'Общая комиссия'!M10+'Общая комиссия'!P10+'Общая комиссия'!Q10)*1.22 -> 7904.6821 | K10: =E10-H10 -> 2305.435 | L10: =F10-I10 -> 2304.9402 | M10: =G10-J10 -> 1816.2836 | N10: =K10/D10-1 -> 0.29770282 | O10: =L10/D10-1 -> 0.29742427 | P10: =M10/D10-1 -> 0.022365109 | Q10: =D10*($T$2/100+1)+H10 -> 7840.3869 | R10: =D10*($T$2/100+1)+I10 -> 8566.1038 | S10: =D10*($T$2/100+1)+J10 -> 10214.198 | U10: 12009.336 | V10: =U10-E10 -> 4173.0299 | W10: =U10-F10 -> 3447.8079 | X10: =U10-G10 -> 2288.3701
A11: Сейф мебельный СМ-20 | B11: 1667684227 | C11: 200х310х200 | D11: ='[1]СМ-20'!F45/1.07 -> 1757.9447 | E11: 5324.119 | F11: 5409.0258 | G11: 5228.0186 | H11: =('Общая комиссия'!G11+'Общая комиссия'!J11+'Общая комиссия'!K11+'Общая комиссия'!L11+'Общая комиссия'!M11+'Общая комиссия'!N11+'Общая комиссия'!Q11)*1.22 -> 3039.5553 | I11: =('Общая комиссия'!H11+'Общая комиссия'!J11+'Общая комиссия'!K11+'Общая комиссия'!L11+'Общая комиссия'!M11+'Общая комиссия'!O11+'Общая комиссия'!Q11)*1.22 -> 3124.4828 | J11: =('Общая комиссия'!I11+'Общая комиссия'!J11+'Общая комиссия'!K11+'Общая комиссия'!L11+'Общая комиссия'!M11+'Общая комиссия'!P11+'Общая комиссия'!Q11)*1.22 -> 3240.9893 | K11: =E11-H11 -> 2284.5637 | L11: =F11-I11 -> 2284.543 | M11: =G11-J11 -> 1987.0292 | N11: =K11/D11-1 -> 0.29956515 | O11: =L11/D11-1 -> 0.29955337 | P11: =M11/D11-1 -> 0.13031385 | Q11: =D11*($T$2/100+1)+H11 -> 5324.8834 | R11: =D11*($T$2/100+1)+I11 -> 5409.811 | S11: =D11*($T$2/100+1)+J11 -> 5526.3174 | U11: 6083.7761 | V11: =U11-E11 -> 759.6571 | W11: =U11-F11 -> 674.75029 | X11: =U11-G11 -> 855.75755
A12: Сейф мебельный СМ-20Э | B12: 1667684137 | C12: 200х310х200 | D12: ='[1]СМ-20Э'!F53/1.07 -> 2118.0062 | E12: 6260.4327 | F12: 6345.3395 | G12: 6070.7009 | H12: =('Общая комиссия'!G12+'Общая комиссия'!J12+'Общая комиссия'!K12+'Общая комиссия'!L12+'Общая комиссия'!M12+'Общая комиссия'!N12+'Общая комиссия'!Q12)*1.22 -> 3507.8995 | I12: =('Общая комиссия'!H12+'Общая комиссия'!J12+'Общая комиссия'!K12+'Общая комиссия'!L12+'Общая комиссия'!M12+'Общая комиссия'!O12+'Общая комиссия'!Q12)*1.22 -> 3592.827 | J12: =('Общая комиссия'!I12+'Общая комиссия'!J12+'Общая комиссия'!K12+'Общая комиссия'!L12+'Общая комиссия'!M12+'Общая комиссия'!P12+'Общая комиссия'!Q12)*1.22 -> 3663.6413 | K12: =E12-H12 -> 2752.5333 | L12: =F12-I12 -> 2752.5126 | M12: =G12-J12 -> 2407.0596 | N12: =K12/D12-1 -> 0.29958696 | O12: =L12/D12-1 -> 0.29957718 | P12: =M12/D12-1 -> 0.13647427 | Q12: =D12*($T$2/100+1)+H12 -> 6261.3076 | R12: =D12*($T$2/100+1)+I12 -> 6346.2351 | S12: =D12*($T$2/100+1)+J12 -> 6417.0494 | U12: 7040.2145 | V12: =U12-E12 -> 779.7818 | W12: =U12-F12 -> 694.87499 | X12: =U12-G12 -> 969.51362
A13: Сейф мебельный СМ-23 | B13: 1672231528 | C13: 229х405х335 | D13: ='[1]СМ-23'!F48/1.07 -> 2310.3243 | E13: 7486.2973 | F13: 7735.5399 | G13: 7876.5144 | H13: =('Общая комиссия'!G13+'Общая комиссия'!J13+'Общая комиссия'!K13+'Общая комиссия'!L13+'Общая комиссия'!M13+'Общая комиссия'!N13+'Общая комиссия'!Q13)*1.22 -> 4484.0269 | I13: =('Общая комиссия'!H13+'Общая комиссия'!J13+'Общая комиссия'!K13+'Общая комиссия'!L13+'Общая комиссия'!M13+'Общая комиссия'!O13+'Общая комиссия'!Q13)*1.22 -> 4733.3303 | J13: =('Общая комиссия'!I13+'Общая комиссия'!J13+'Общая комиссия'!K13+'Общая комиссия'!L13+'Общая комиссия'!M13+'Общая комиссия'!P13+'Общая комиссия'!Q13)*1.22 -> 5322.6389 | K13: =E13-H13 -> 3002.2704 | L13: =F13-I13 -> 3002.2096 | M13: =G13-J13 -> 2553.8756 | N13: =K13/D13-1 -> 0.2995017 | O13: =L13/D13-1 -> 0.29947539 | P13: =M13/D13-1 -> 0.10541863 | Q13: =D13*($T$2/100+1)+H13 -> 7487.4485 | R13: =D13*($T$2/100+1)+I13 -> 7736.7519 | S13: =D13*($T$2/100+1)+J13 -> 8326.0605 | U13: 9118.4065 | V13: =U13-E13 -> 1632.1092 | W13: =U13-F13 -> 1382.8666 | X13: =U13-G13 -> 1241.8921
A14: Сейф мебельный СМ-23Э | B14: 1672231536 | C14: 229х405х335 | D14: ='[1]СМ-23Э'!F50/1.07 -> 2662.5406 | E14: 8274.1354 | F14: 8460.3826 | G14: 8400.691 | H14: =('Общая комиссия'!G14+'Общая комиссия'!J14+'Общая комиссия'!K14+'Общая комиссия'!L14+'Общая комиссия'!M14+'Общая комиссия'!N14+'Общая комиссия'!Q14)*1.22 -> 4814.0535 | I14: =('Общая комиссия'!H14+'Общая комиссия'!J14+'Общая комиссия'!K14+'Общая комиссия'!L14+'Общая комиссия'!M14+'Общая комиссия'!O14+'Общая комиссия'!Q14)*1.22 -> 5000.3462 | J14: =('Общая комиссия'!I14+'Общая комиссия'!J14+'Общая комиссия'!K14+'Общая комиссия'!L14+'Общая комиссия'!M14+'Общая комиссия'!P14+'Общая комиссия'!Q14)*1.22 -> 5418.7737 | K14: =E14-H14 -> 3460.0819 | L14: =F14-I14 -> 3460.0365 | M14: =G14-J14 -> 2981.9173 | N14: =K14/D14-1 -> 0.29954148 | O14: =L14/D14-1 -> 0.29952441 | P14: =M14/D14-1 -> 0.1199519 | Q14: =D14*($T$2/100+1)+H14 -> 8275.3563 | R14: =D14*($T$2/100+1)+I14 -> 8461.6489 | S14: =D14*($T$2/100+1)+J14 -> 8880.0764 | U14: 9977.525 | V14: =U14-E14 -> 1703.3896 | W14: =U14-F14 -> 1517.1424 | X14: =U14-G14 -> 1576.834
A15: Сейф мебельный СМ-25 | B15: 1672261347 | C15: 250х350х250 | D15: ='[1]СМ-25'!F45/1.07 -> 1970.8381 | E15: 6103.6318 | F15: 6320.0072 | G15: 6210.5943 | H15: =('Общая комиссия'!G15+'Общая комиссия'!J15+'Общая комиссия'!K15+'Общая комиссия'!L15+'Общая комиссия'!M15+'Общая комиссия'!N15+'Общая комиссия'!Q15)*1.22 -> 3542.4396 | I15: =('Общая комиссия'!H15+'Общая комиссия'!J15+'Общая комиссия'!K15+'Общая комиссия'!L15+'Общая комиссия'!M15+'Общая комиссия'!O15+'Общая комиссия'!Q15)*1.22 -> 3758.8678 | J15: =('Общая комиссия'!I15+'Общая комиссия'!J15+'Общая комиссия'!K15+'Общая комиссия'!L15+'Общая комиссия'!M15+'Общая комиссия'!P15+'Общая комиссия'!Q15)*1.22 -> 4002.9103 | K15: =E15-H15 -> 2561.1922 | L15: =F15-I15 -> 2561.1394 | M15: =G15-J15 -> 2207.6839 | N15: =K15/D15-1 -> 0.29954467 | O15: =L15/D15-1 -> 0.29951788 | P15: =M15/D15-1 -> 0.12017517 | Q15: =D15*($T$2/100+1)+H15 -> 6104.5292 | R15: =D15*($T$2/100+1)+I15 -> 6320.9574 | S15: =D15*($T$2/100+1)+J15 -> 6564.9999 | U15: 7396.2062 | V15: =U15-E15 -> 1292.5744 | W15: =U15-F15 -> 1076.199 | X15: =U15-G15 -> 1185.612
A16: Сейф мебельный СМ-25Э | B16: 1672260987 | C16: 250х350х250 | D16: ='[1]СМ-25Э'!F50/1.07 -> 2358.8977 | E16: 7112.7525 | F16: 7329.1279 | G16: 7118.8029 | H16: =('Общая комиссия'!G16+'Общая комиссия'!J16+'Общая комиссия'!K16+'Общая комиссия'!L16+'Общая комиссия'!M16+'Общая комиссия'!N16+'Общая комиссия'!Q16)*1.22 -> 4047.2018 | I16: =('Общая комиссия'!H16+'Общая комиссия'!J16+'Общая комиссия'!K16+'Общая комиссия'!L16+'Общая комиссия'!M16+'Общая комиссия'!O16+'Общая комиссия'!Q16)*1.22 -> 4263.63 | J16: =('Общая комиссия'!I16+'Общая комиссия'!J16+'Общая комиссия'!K16+'Общая комиссия'!L16+'Общая комиссия'!M16+'Общая комиссия'!P16+'Общая комиссия'!Q16)*1.22 -> 4458.4274 | K16: =E16-H16 -> 3065.5507 | L16: =F16-I16 -> 3065.4979 | M16: =G16-J16 -> 2660.3755 | N16: =K16/D16-1 -> 0.29956914 | O16: =L16/D16-1 -> 0.29954676 | P16: =M16/D16-1 -> 0.1278045 | Q16: =D16*($T$2/100+1)+H16 -> 7113.7689 | R16: =D16*($T$2/100+1)+I16 -> 7330.1971 | S16: =D16*($T$2/100+1)+J16 -> 7524.9944 | U16: 8427.0167 | V16: =U16-E16 -> 1314.2642 | W16: =U16-F16 -> 1097.8888 | X16: =U16-G16 -> 1308.2138
A17: Сейф мебельный СМ-30 | B17: 1706788520 | C17: 300х380х300 | D17: ='[1]СМ-30'!F45/1.07 -> 2298.7606 | E17: 7465.4968 | F17: 7714.7394 | G17: 7857.7939 | H17: =('Общая комиссия'!G17+'Общая комиссия'!J17+'Общая комиссия'!K17+'Общая комиссия'!L17+'Общая комиссия'!M17+'Общая комиссия'!N17+'Общая комиссия'!Q17)*1.22 -> 4478.2585 | I17: =('Общая комиссия'!H17+'Общая комиссия'!J17+'Общая комиссия'!K17+'Общая комиссия'!L17+'Общая комиссия'!M17+'Общая комиссия'!O17+'Общая комиссия'!Q17)*1.22 -> 4727.5619 | J17: =('Общая комиссия'!I17+'Общая комиссия'!J17+'Общая комиссия'!K17+'Общая комиссия'!L17+'Общая комиссия'!M17+'Общая комиссия'!P17+'Общая комиссия'!Q17)*1.22 -> 5317.8855 | K17: =E17-H17 -> 2987.2383 | L17: =F17-I17 -> 2987.1775 | M17: =G17-J17 -> 2539.9084 | N17: =K17/D17-1 -> 0.29949953 | O17: =L17/D17-1 -> 0.29947308 | P17: =M17/D17-1 -> 0.10490343 | Q17: =D17*($T$2/100+1)+H17 -> 7466.6472 | R17: =D17*($T$2/100+1)+I17 -> 7715.9506 | S17: =D17*($T$2/100+1)+J17 -> 8306.2743 | U17: 9237.6693 | V17: =U17-E17 -> 1772.1725 | W17: =U17-F17 -> 1522.93 | X17: =U17-G17 -> 1379.8754
A18: Сейф мебельный СМ-30Э | B18: 1706788784 | C18: 300х380х300 | D18: ='[1]СМ-30Э'!F53/1.07 -> 2799.4389 | E18: 8767.4741 | F18: 9016.7167 | G18: 9029.5735 | H18: =('Общая комиссия'!G18+'Общая комиссия'!J18+'Общая комиссия'!K18+'Общая комиссия'!L18+'Общая комиссия'!M18+'Общая комиссия'!N18+'Общая комиссия'!Q18)*1.22 -> 5129.5075 | I18: =('Общая комиссия'!H18+'Общая комиссия'!J18+'Общая комиссия'!K18+'Общая комиссия'!L18+'Общая комиссия'!M18+'Общая комиссия'!O18+'Общая комиссия'!Q18)*1.22 -> 5378.8109 | J18: =('Общая комиссия'!I18+'Общая комиссия'!J18+'Общая комиссия'!K18+'Общая комиссия'!L18+'Общая комиссия'!M18+'Общая комиссия'!P18+'Общая комиссия'!Q18)*1.22 -> 5905.5981 | K18: =E18-H18 -> 3637.9666 | L18: =F18-I18 -> 3637.9058 | M18: =G18-J18 -> 3123.9755 | N18: =K18/D18-1 -> 0.29953421 | O18: =L18/D18-1 -> 0.29951249 | P18: =M18/D18-1 -> 0.11592917 | Q18: =D18*($T$2/100+1)+H18 -> 8768.7781 | R18: =D18*($T$2/100+1)+I18 -> 9018.0814 | S18: =D18*($T$2/100+1)+J18 -> 9544.8686 | U18: 10567.631 | V18: =U18-E18 -> 1800.1568 | W18: =U18-F18 -> 1550.9142 | X18: =U18-G18 -> 1538.0573
A19: Сейф мебельный СМ-50 | B19: 1672277739 | C19: 500х350х310 | D19: ='[1]СМ-50'!F48/1.07 -> 2878.1785 | E19: 9500.6294 | F19: 9821.0842 | G19: 10051.774 | H19: =('Общая комиссия'!G19+'Общая комиссия'!J19+'Общая комиссия'!K19+'Общая комиссия'!L19+'Общая комиссия'!M19+'Общая комиссия'!N19+'Общая комиссия'!Q19)*1.22 -> 5760.4838 | I19: =('Общая комиссия'!H19+'Общая комиссия'!J19+'Общая комиссия'!K19+'Общая комиссия'!L19+'Общая комиссия'!M19+'Общая комиссия'!O19+'Общая комиссия'!Q19)*1.22 -> 6081.0168 | J19: =('Общая комиссия'!I19+'Общая комиссия'!J19+'Общая комиссия'!K19+'Общая комиссия'!L19+'Общая комиссия'!M19+'Общая комиссия'!P19+'Общая комиссия'!Q19)*1.22 -> 6883.8692 | K19: =E19-H19 -> 3740.1456 | L19: =F19-I19 -> 3740.0674 | M19: =G19-J19 -> 3167.9045 | N19: =K19/D19-1 -> 0.29948356 | O19: =L19/D19-1 -> 0.2994564 | P19: =M19/D19-1 -> 0.10066297 | Q19: =D19*($T$2/100+1)+H19 -> 9502.1158 | R19: =D19*($T$2/100+1)+I19 -> 9822.6487 | S19: =D19*($T$2/100+1)+J19 -> 10625.501 | U19: 12417.621 | V19: =U19-E19 -> 2916.9918 | W19: =U19-F19 -> 2596.5371 | X19: =U19-G19 -> 2365.8476
A20: Сейф мебельный СМ-50Э | B20: 1672277747 | C20: 500х350х310 | D20: ='[1]СМ-50Э'!F53/1.07 -> 3279.2426 | E20: 10543.567 | F20: 10864.022 | G20: 10990.418 | H20: =('Общая комиссия'!G20+'Общая комиссия'!J20+'Общая комиссия'!K20+'Общая комиссия'!L20+'Общая комиссия'!M20+'Общая комиссия'!N20+'Общая комиссия'!Q20)*1.22 -> 6282.1615 | I20: =('Общая комиссия'!H20+'Общая комиссия'!J20+'Общая комиссия'!K20+'Общая комиссия'!L20+'Общая комиссия'!M20+'Общая комиссия'!O20+'Общая комиссия'!Q20)*1.22 -> 6602.6944 | J20: =('Общая комиссия'!I20+'Общая комиссия'!J20+'Общая комиссия'!K20+'Общая комиссия'!L20+'Общая комиссия'!M20+'Общая комиссия'!P20+'Общая комиссия'!Q20)*1.22 -> 7354.6515 | K20: =E20-H20 -> 4261.406 | L20: =F20-I20 -> 4261.3279 | M20: =G20-J20 -> 3635.7665 | N20: =K20/D20-1 -> 0.29950923 | O20: =L20/D20-1 -> 0.29948539 | P20: =M20/D20-1 -> 0.1087214 | Q20: =D20*($T$2/100+1)+H20 -> 10545.177 | R20: =D20*($T$2/100+1)+I20 -> 10865.71 | S20: =D20*($T$2/100+1)+J20 -> 11617.667 | U20: 13482.976 | V20: =U20-E20 -> 2939.4082 | W20: =U20-F20 -> 2618.9534 | X20: =U20-G20 -> 2492.5577
A21: Стеллаж металлический СТ-СП | B21: 258467589 | C21: 2000x1000x400, 4 150кг | D21: ='[1]40(4) NEW'!F44/1.07 -> 2793.8175 | E21: 7814.1939 | F21: 8027.5475 | G21: 8092.1113 | H21: =('Общая комиссия'!G21+'Общая комиссия'!J21+'Общая комиссия'!K21+'Общая комиссия'!L21+'Общая комиссия'!M21+'Общая комиссия'!N21+'Общая комиссия'!Q21)*1.22 -> 4182.4868 | I21: =('Общая комиссия'!H21+'Общая комиссия'!J21+'Общая комиссия'!K21+'Общая комиссия'!L21+'Общая комиссия'!M21+'Общая комиссия'!O21+'Общая комиссия'!Q21)*1.22 -> 4395.8529 | J21: =('Общая комиссия'!I21+'Общая комиссия'!J21+'Общая комиссия'!K21+'Общая комиссия'!L21+'Общая комиссия'!M21+'Общая комиссия'!P21+'Общая комиссия'!Q21)*1.22 -> 4986.6399 | K21: =E21-H21 -> 3631.7071 | L21: =F21-I21 -> 3631.6947 | M21: =G21-J21 -> 3105.4713 | N21: =K21/D21-1 -> 0.29990849 | O21: =L21/D21-1 -> 0.29990403 | P21: =M21/D21-1 -> 0.11155125 | Q21: =D21*($T$2/100+1)+H21 -> 7814.4496 | R21: =D21*($T$2/100+1)+I21 -> 8027.8157 | S21: =D21*($T$2/100+1)+J21 -> 8618.6027 | U21: 9587.7421 | V21: =U21-E21 -> 1773.5482 | W21: =U21-F21 -> 1560.1946 | X21: =U21-G21 -> 1495.6309
A22: Стеллаж металлический СТ-СП | B22: 258473499 | C22: 2000x1000x500, 4 150кг | D22: ='[1]50(4) NEW'!F44/1.07 -> 3063.8194 | E22: 9152.8146 | F22: 8996.8845 | G22: 9158.6903 | H22: =('Общая комиссия'!G22+'Общая комиссия'!J22+'Общая комиссия'!K22+'Общая комиссия'!L22+'Общая комиссия'!M22+'Общая комиссия'!N22+'Общая комиссия'!Q22)*1.22 -> 5170.1512 | I22: =('Общая комиссия'!H22+'Общая комиссия'!J22+'Общая комиссия'!K22+'Общая комиссия'!L22+'Общая комиссия'!M22+'Общая комиссия'!O22+'Общая комиссия'!Q22)*1.22 -> 5014.2315 | J22: =('Общая комиссия'!I22+'Общая комиссия'!J22+'Общая комиссия'!K22+'Общая комиссия'!L22+'Общая комиссия'!M22+'Общая комиссия'!P22+'Общая комиссия'!Q22)*1.22 -> 5771.6246 | K22: =E22-H22 -> 3982.6634 | L22: =F22-I22 -> 3982.653 | M22: =G22-J22 -> 3387.0658 | N22: =K22/D22-1 -> 0.29990149 | O22: =L22/D22-1 -> 0.29989809 | P22: =M22/D22-1 -> 0.10550437 | Q22: =D22*($T$2/100+1)+H22 -> 9153.1164 | R22: =D22*($T$2/100+1)+I22 -> 8997.1968 | S22: =D22*($T$2/100+1)+J22 -> 9754.5898 | U22: 11568.409 | V22: =U22-E22 -> 2415.594 | W22: =U22-F22 -> 2571.5241 | X22: =U22-G22 -> 2409.7183
A23: Стеллаж металлический СТ-СП | B23: 888213183 | C23: 2000х1000х400, 6 150кг | D23: ='[1]40(6) NEW'!F44/1.07 -> 3625.801 | E23: 9768.511 | F23: 10533.338 | G23: 10813.345 | H23: =('Общая комиссия'!G23+'Общая комиссия'!J23+'Общая комиссия'!K23+'Общая комиссия'!L23+'Общая комиссия'!M23+'Общая комиссия'!N23+'Общая комиссия'!Q23)*1.22 -> 5055.2958 | I23: =('Общая комиссия'!H23+'Общая комиссия'!J23+'Общая комиссия'!K23+'Общая комиссия'!L23+'Общая комиссия'!M23+'Общая комиссия'!O23+'Общая комиссия'!Q23)*1.22 -> 5820.1479 | J23: =('Общая комиссия'!I23+'Общая комиссия'!J23+'Общая комиссия'!K23+'Общая комиссия'!L23+'Общая комиссия'!M23+'Общая комиссия'!P23+'Общая комиссия'!Q23)*1.22 -> 6803.3487 | K23: =E23-H23 -> 4713.2152 | L23: =F23-I23 -> 4713.1901 | M23: =G23-J23 -> 4009.9959 | N23: =K23/D23-1 -> 0.29991005 | O23: =L23/D23-1 -> 0.29990312 | P23: =M23/D23-1 -> 0.10596138 | Q23: =D23*($T$2/100+1)+H23 -> 9768.8372 | R23: =D23*($T$2/100+1)+I23 -> 10533.689 | S23: =D23*($T$2/100+1)+J23 -> 11516.89 | U23: 12214.235 | V23: =U23-E23 -> 2445.7243 | W23: =U23-F23 -> 1680.8973 | X23: =U23-G23 -> 1400.8908
A24: ШБС-01 мини | B24: 906309058 | C24: 350х440х360 | D24: ='[1]ШБС-01 мини'!F49/1.07 -> 2638.1991 | E24: 9149.4402 | F24: 9524.6735 | G24: 10095.599 | H24: =('Общая комиссия'!G24+'Общая комиссия'!J24+'Общая комиссия'!K24+'Общая комиссия'!L24+'Общая комиссия'!M24+'Общая комиссия'!N24+'Общая комиссия'!Q24)*1.22 -> 5721.276 | I24: =('Общая комиссия'!H24+'Общая комиссия'!J24+'Общая комиссия'!K24+'Общая комиссия'!L24+'Общая комиссия'!M24+'Общая комиссия'!O24+'Общая комиссия'!Q24)*1.22 -> 6096.6008 | J24: =('Общая комиссия'!I24+'Общая комиссия'!J24+'Общая комиссия'!K24+'Общая комиссия'!L24+'Общая комиссия'!M24+'Общая комиссия'!P24+'Общая комиссия'!Q24)*1.22 -> 7242.2663 | K24: =E24-H24 -> 3428.1642 | L24: =F24-I24 -> 3428.0727 | M24: =G24-J24 -> 2853.3324 | N24: =K24/D24-1 -> 0.29943348 | O24: =L24/D24-1 -> 0.29939878 | P24: =M24/D24-1 -> 0.081545511 | Q24: =D24*($T$2/100+1)+H24 -> 9150.9348 | R24: =D24*($T$2/100+1)+I24 -> 9526.2596 | S24: =D24*($T$2/100+1)+J24 -> 10671.925 | U24: 12153.617 | V24: =U24-E24 -> 3004.1773 | W24: =U24-F24 -> 2628.944 | X24: =U24-G24 -> 2058.0188
A25: ШБС-01 мини Т | B25: 906309023 | C25: 350х440х360 | D25: ='[1]ШБС-01 мини Т'!F48/1.07 -> 2818.2769 | E25: 9608.4492 | F25: 9983.6826 | G25: 10508.707 | H25: =('Общая комиссия'!G25+'Общая комиссия'!J25+'Общая комиссия'!K25+'Общая комиссия'!L25+'Общая комиссия'!M25+'Общая комиссия'!N25+'Общая комиссия'!Q25)*1.22 -> 5946.2363 | I25: =('Общая комиссия'!H25+'Общая комиссия'!J25+'Общая комиссия'!K25+'Общая комиссия'!L25+'Общая комиссия'!M25+'Общая комиссия'!O25+'Общая комиссия'!Q25)*1.22 -> 6321.5612 | J25: =('Общая комиссия'!I25+'Общая комиссия'!J25+'Общая комиссия'!K25+'Общая комиссия'!L25+'Общая комиссия'!M25+'Общая комиссия'!P25+'Общая комиссия'!Q25)*1.22 -> 7444.827 | K25: =E25-H25 -> 3662.2129 | L25: =F25-I25 -> 3662.1214 | M25: =G25-J25 -> 3063.8798 | N25: =K25/D25-1 -> 0.29945108 | O25: =L25/D25-1 -> 0.2994186 | P25: =M25/D25-1 -> 0.087146492 | Q25: =D25*($T$2/100+1)+H25 -> 9609.9963 | R25: =D25*($T$2/100+1)+I25 -> 9985.3211 | S25: =D25*($T$2/100+1)+J25 -> 11108.587 | U25: 12481.982 | V25: =U25-E25 -> 2873.5327 | W25: =U25-F25 -> 2498.2994 | X25: =U25-G25 -> 1973.2751
A26: Шкаф бухгалтерский ШБС-01-17 | B26: 2948118892 | C26: 1700x500x400 | D26: =9734/1.07 -> 9097.1963 | E26: 31197.987 | F26: 34076.602 | G26: 36915.344 | H26: =('Общая комиссия'!G26+'Общая комиссия'!J26+'Общая комиссия'!K26+'Общая комиссия'!L26+'Общая комиссия'!M26+'Общая комиссия'!N26+'Общая комиссия'!Q26)*1.22 -> 19376.68 | I26: =('Общая комиссия'!H26+'Общая комиссия'!J26+'Общая комиссия'!K26+'Общая комиссия'!L26+'Общая комиссия'!M26+'Общая комиссия'!O26+'Общая комиссия'!Q26)*1.22 -> 22255.997 | J26: =('Общая комиссия'!I26+'Общая комиссия'!J26+'Общая комиссия'!K26+'Общая комиссия'!L26+'Общая комиссия'!M26+'Общая комиссия'!P26+'Общая комиссия'!Q26)*1.22 -> 27196.505 | K26: =E26-H26 -> 11821.307 | L26: =F26-I26 -> 11820.605 | M26: =G26-J26 -> 9718.8386 | N26: =K26/D26-1 -> 0.29944506 | O26: =L26/D26-1 -> 0.29936787 | P26: =M26/D26-1 -> 0.068333397 | Q26: =D26*($T$2/100+1)+H26 -> 31203.035 | R26: =D26*($T$2/100+1)+I26 -> 34082.352 | S26: =D26*($T$2/100+1)+J26 -> 39022.86 | U26: 42319.478 | V26: =U26-E26 -> 11121.491 | W26: =U26-F26 -> 8242.8762 | X26: =U26-G26 -> 5404.1339
A27: Шкаф бухгалтерский ШБС-02-17 | B27: 2806318479 | C27: 1700x500x400 | D27: =10727/1.07 -> 10025.234 | E27: 33611.28 | F27: 36489.895 | G27: 39087.308 | H27: =('Общая комиссия'!G27+'Общая комиссия'!J27+'Общая комиссия'!K27+'Общая комиссия'!L27+'Общая комиссия'!M27+'Общая комиссия'!N27+'Общая комиссия'!Q27)*1.22 -> 20583.809 | I27: =('Общая комиссия'!H27+'Общая комиссия'!J27+'Общая комиссия'!K27+'Общая комиссия'!L27+'Общая комиссия'!M27+'Общая комиссия'!O27+'Общая комиссия'!Q27)*1.22 -> 23463.126 | J27: =('Общая комиссия'!I27+'Общая комиссия'!J27+'Общая комиссия'!K27+'Общая комиссия'!L27+'Общая комиссия'!M27+'Общая комиссия'!P27+'Общая комиссия'!Q27)*1.22 -> 28285.866 | K27: =E27-H27 -> 13027.471 | L27: =F27-I27 -> 13026.769 | M27: =G27-J27 -> 10801.442 | N27: =K27/D27-1 -> 0.29946805 | O27: =L27/D27-1 -> 0.29939801 | P27: =M27/D27-1 -> 0.077425469 | Q27: =D27*($T$2/100+1)+H27 -> 33616.613 | R27: =D27*($T$2/100+1)+I27 -> 36495.93 | S27: =D27*($T$2/100+1)+J27 -> 41318.67 | U27: 44784.641 | V27: =U27-E27 -> 11173.361 | W27: =U27-F27 -> 8294.7463 | X27: =U27-G27 -> 5697.3334
A28: Стеллаж металлический СТ-СПЭ | B28: 3558967942 | C28: 2000x1000x400, 4 | D28: ='[1]СПЭ(4)'!S42/1.07 -> 2072.4981 | E28: 7080.6951 | F28: 7324.4598 | G28: 7582.9585 | H28: =('Общая комиссия'!G28+'Общая комиссия'!J28+'Общая комиссия'!K28+'Общая комиссия'!L28+'Общая комиссия'!M28+'Общая комиссия'!N28+'Общая комиссия'!Q28)*1.22 -> 4387.5897 | I28: =('Общая комиссия'!H28+'Общая комиссия'!J28+'Общая комиссия'!K28+'Общая комиссия'!L28+'Общая комиссия'!M28+'Общая комиссия'!O28+'Общая комиссия'!Q28)*1.22 -> 4631.4139 | J28: =('Общая комиссия'!I28+'Общая комиссия'!J28+'Общая комиссия'!K28+'Общая комиссия'!L28+'Общая комиссия'!M28+'Общая комиссия'!P28+'Общая комиссия'!Q28)*1.22 -> 5321.5672 | K28: =E28-H28 -> 2693.1054 | L28: =F28-I28 -> 2693.0459 | M28: =G28-J28 -> 2261.3913 | N28: =K28/D28-1 -> 0.29944893 | O28: =L28/D28-1 -> 0.29942024 | P28: =M28/D28-1 -> 0.091142757 | Q28: =D28*($T$2/100+1)+H28 -> 7081.8372 | R28: =D28*($T$2/100+1)+I28 -> 7325.6613 | S28: =D28*($T$2/100+1)+J28 -> 8015.8147 | U28: 8671.1246 | V28: =U28-E28 -> 1590.4295 | W28: =U28-F28 -> 1346.6648 | X28: =U28-G28 -> 1088.1661
A29: Стеллаж металлический СТ-СПЭ | B29: 3558953998 | C29: 2000x1000x500, 4 | D29: ='[1]СПЭ(5)'!U36/1.07 -> 2282.1002 | E29: 8426.4492 | F29: 8275.9949 | G29: 8661.1933 | H29: =('Общая комиссия'!G29+'Общая комиссия'!J29+'Общая комиссия'!K29+'Общая комиссия'!L29+'Общая комиссия'!M29+'Общая комиссия'!N29+'Общая комиссия'!Q29)*1.22 -> 5461.089 | I29: =('Общая комиссия'!H29+'Общая комиссия'!J29+'Общая комиссия'!K29+'Общая комиссия'!L29+'Общая комиссия'!M29+'Общая комиссия'!O29+'Общая комиссия'!Q29)*1.22 -> 5310.665 | J29: =('Общая комиссия'!I29+'Общая комиссия'!J29+'Общая комиссия'!K29+'Общая комиссия'!L29+'Общая комиссия'!M29+'Общая комиссия'!P29+'Общая комиссия'!Q29)*1.22 -> 6188.9179 | K29: =E29-H29 -> 2965.3603 | L29: =F29-I29 -> 2965.3299 | M29: =G29-J29 -> 2472.2755 | N29: =K29/D29-1 -> 0.29939968 | O29: =L29/D29-1 -> 0.29938637 | P29: =M29/D29-1 -> 0.083333459 | Q29: =D29*($T$2/100+1)+H29 -> 8427.8192 | R29: =D29*($T$2/100+1)+I29 -> 8277.3953 | S29: =D29*($T$2/100+1)+J29 -> 9155.6481 | U29: 9331.338 | V29: =U29-E29 -> 904.88872 | W29: =U29-F29 -> 1055.3431 | X29: =U29-G29 -> 670.14461
A30: Стеллаж металлический СТ-СПЭ | B30: 3558882434 | C30: 2000х1000х400, 6 | D30: ='[1]СПЭ(4)'!S43/1.07 -> 2738.5513 | E30: 8920.6157 | F30: 9766.7582 | G30: 10313.475 | H30: =('Общая комиссия'!G30+'Общая комиссия'!J30+'Общая комиссия'!K30+'Общая комиссия'!L30+'Общая комиссия'!M30+'Общая комиссия'!N30+'Общая комиссия'!Q30)*1.22 -> 5361.9539 | I30: =('Общая комиссия'!H30+'Общая комиссия'!J30+'Общая комиссия'!K30+'Общая комиссия'!L30+'Общая комиссия'!M30+'Общая комиссия'!O30+'Общая комиссия'!Q30)*1.22 -> 6208.2357 | J30: =('Общая комиссия'!I30+'Общая комиссия'!J30+'Общая комиссия'!K30+'Общая комиссия'!L30+'Общая комиссия'!M30+'Общая комиссия'!P30+'Общая комиссия'!Q30)*1.22 -> 7342.0874 | K30: =E30-H30 -> 3558.6618 | L30: =F30-I30 -> 3558.5225 | M30: =G30-J30 -> 2971.3875 | N30: =K30/D30-1 -> 0.29946874 | O30: =L30/D30-1 -> 0.29941786 | P30: =M30/D30-1 -> 0.085021648 | Q30: =D30*($T$2/100+1)+H30 -> 8922.0706 | R30: =D30*($T$2/100+1)+I30 -> 9768.3524 | S30: =D30*($T$2/100+1)+J30 -> 10902.204 | U30: 12027.023 | V30: =U30-E30 -> 3106.4072 | W30: =U30-F30 -> 2260.2648 | X30: =U30-G30 -> 1713.5481
A31: ШО-5 | B31: 3541466873 | C31: =C26 -> 1700x500x400 | D31: =D26+2500 -> 11597.196 | E31: 42907.582 | F31: 46172.161 | G31: 48638.865 | H31: =('Общая комиссия'!G31+'Общая комиссия'!J31+'Общая комиссия'!K31+'Общая комиссия'!L31+'Общая комиссия'!M31+'Общая комиссия'!N31+'Общая комиссия'!Q31)*1.22 -> 27851.182 | I31: =('Общая комиссия'!H31+'Общая комиссия'!J31+'Общая комиссия'!K31+'Общая комиссия'!L31+'Общая комиссия'!M31+'Общая комиссия'!O31+'Общая комиссия'!Q31)*1.22 -> 31117.989 | J31: =('Общая комиссия'!I31+'Общая комиссия'!J31+'Общая комиссия'!K31+'Общая комиссия'!L31+'Общая комиссия'!M31+'Общая комиссия'!P31+'Общая комиссия'!Q31)*1.22 -> 36027.412 | K31: =E31-H31 -> 15056.4 | L31: =F31-I31 -> 15054.172 | M31: =G31-J31 -> 12611.454 | N31: =K31/D31-1 -> 0.29827931 | O31: =L31/D31-1 -> 0.29808722 | P31: =M31/D31-1 -> 0.087457133 | Q31: =D31*($T$2/100+1)+H31 -> 42927.537 | R31: =D31*($T$2/100+1)+I31 -> 46194.344 | S31: =D31*($T$2/100+1)+J31 -> 51103.767 | U31: 56203.001 | V31: =U31-E31 -> 13295.419 | W31: =U31-F31 -> 10030.84 | X31: =U31-G31 -> 7564.1359
A32: ШО-1 | B32: 3541430418 | D32: ='расход ШО1'!F40/1.07 -> 5469.87 | E32: 18800.428 | F32: 19225.973 | G32: 19031.025 | H32: =('Общая комиссия'!G32+'Общая комиссия'!J32+'Общая комиссия'!K32+'Общая комиссия'!L32+'Общая комиссия'!M32+'Общая комиссия'!N32+'Общая комиссия'!Q32)*1.22 -> 11697.844 | I32: =('Общая комиссия'!H32+'Общая комиссия'!J32+'Общая комиссия'!K32+'Общая комиссия'!L32+'Общая комиссия'!M32+'Общая комиссия'!O32+'Общая комиссия'!Q32)*1.22 -> 12123.679 | J32: =('Общая комиссия'!I32+'Общая комиссия'!J32+'Общая комиссия'!K32+'Общая комиссия'!L32+'Общая комиссия'!M32+'Общая комиссия'!P32+'Общая комиссия'!Q32)*1.22 -> 12883.707 | K32: =E32-H32 -> 7102.584 | L32: =F32-I32 -> 7102.2936 | M32: =G32-J32 -> 6147.318 | N32: =K32/D32-1 -> 0.29849229 | O32: =L32/D32-1 -> 0.2984392 | P32: =M32/D32-1 -> 0.12385084 | Q32: =D32*($T$2/100+1)+H32 -> 18808.675 | R32: =D32*($T$2/100+1)+I32 -> 19234.51 | S32: =D32*($T$2/100+1)+J32 -> 19994.538 | U32: 22673.872 | V32: =U32-E32 -> 3873.4433 | W32: =U32-F32 -> 3447.8986 | X32: =U32-G32 -> 3642.8469
A33: ШО-2 | B33: 3541476893 | D33: ='расход ШО2'!F40/1.07 -> 3522.7853 | E33: 12341.182 | F33: 12617.631 | G33: 12479.678 | H33: =('Общая комиссия'!G33+'Общая комиссия'!J33+'Общая комиссия'!K33+'Общая комиссия'!L33+'Общая комиссия'!M33+'Общая комиссия'!N33+'Общая комиссия'!Q33)*1.22 -> 7767.0612 | I33: =('Общая комиссия'!H33+'Общая комиссия'!J33+'Общая комиссия'!K33+'Общая комиссия'!L33+'Общая комиссия'!M33+'Общая комиссия'!O33+'Общая комиссия'!Q33)*1.22 -> 8043.6986 | J33: =('Общая комиссия'!I33+'Общая комиссия'!J33+'Общая комиссия'!K33+'Общая комиссия'!L33+'Общая комиссия'!M33+'Общая комиссия'!P33+'Общая комиссия'!Q33)*1.22 -> 8531.9687 | K33: =E33-H33 -> 4574.1206 | L33: =F33-I33 -> 4573.932 | M33: =G33-J33 -> 3947.7094 | N33: =K33/D33-1 -> 0.29843866 | O33: =L33/D33-1 -> 0.29838511 | P33: =M33/D33-1 -> 0.12062163 | Q33: =D33*($T$2/100+1)+H33 -> 12346.682 | R33: =D33*($T$2/100+1)+I33 -> 12623.319 | S33: =D33*($T$2/100+1)+J33 -> 13111.59 | U33: 14765.313 | V33: =U33-E33 -> 2424.1313 | W33: =U33-F33 -> 2147.6826 | X33: =U33-G33 -> 2285.6351
A34: ШО-3 | B34: 3541448015 | D34: ='расход ШО3'!F41/1.07 -> 3511.8574 | E34: 12087.791 | F34: 12370.452 | G34: 12170.556 | H34: =('Общая комиссия'!G34+'Общая комиссия'!J34+'Общая комиссия'!K34+'Общая комиссия'!L34+'Общая комиссия'!M34+'Общая комиссия'!N34+'Общая комиссия'!Q34)*1.22 -> 7527.6855 | I34: =('Общая комиссия'!H34+'Общая комиссия'!J34+'Общая комиссия'!K34+'Общая комиссия'!L34+'Общая комиссия'!M34+'Общая комиссия'!O34+'Общая комиссия'!Q34)*1.22 -> 7810.5394 | J34: =('Общая комиссия'!I34+'Общая комиссия'!J34+'Общая комиссия'!K34+'Общая комиссия'!L34+'Общая комиссия'!M34+'Общая комиссия'!P34+'Общая комиссия'!Q34)*1.22 -> 8221.3091 | K34: =E34-H34 -> 4560.1058 | L34: =F34-I34 -> 4559.913 | M34: =G34-J34 -> 3949.2465 | N34: =K34/D34-1 -> 0.29848831 | O34: =L34/D34-1 -> 0.29843339 | P34: =M34/D34-1 -> 0.12454638 | Q34: =D34*($T$2/100+1)+H34 -> 12093.1 | R34: =D34*($T$2/100+1)+I34 -> 12375.954 | S34: =D34*($T$2/100+1)+J34 -> 12786.724 | U34: 14303.289 | V34: =U34-E34 -> 2215.4975 | W34: =U34-F34 -> 1932.8364 | X34: =U34-G34 -> 2132.7331
A35: ШО-4 | B35: 3541452420 | D35: ='расход ШО4'!F41/1.07 -> 6486.9429 | E35: 22478.051 | F35: 23096.178 | G35: 23059.341 | H35: =('Общая комиссия'!G35+'Общая комиссия'!J35+'Общая комиссия'!K35+'Общая комиссия'!L35+'Общая комиссия'!M35+'Общая комиссия'!N35+'Общая комиссия'!Q35)*1.22 -> 14054.953 | I35: =('Общая комиссия'!H35+'Общая комиссия'!J35+'Общая комиссия'!K35+'Общая комиссия'!L35+'Общая комиссия'!M35+'Общая комиссия'!O35+'Общая комиссия'!Q35)*1.22 -> 14673.502 | J35: =('Общая комиссия'!I35+'Общая комиссия'!J35+'Общая комиссия'!K35+'Общая комиссия'!L35+'Общая комиссия'!M35+'Общая комиссия'!P35+'Общая комиссия'!Q35)*1.22 -> 15793.918 | K35: =E35-H35 -> 8423.0979 | L35: =F35-I35 -> 8422.6761 | M35: =G35-J35 -> 7265.4237 | N35: =K35/D35-1 -> 0.29846957 | O35: =L35/D35-1 -> 0.29840454 | P35: =M35/D35-1 -> 0.12000735 | Q35: =D35*($T$2/100+1)+H35 -> 22487.979 | R35: =D35*($T$2/100+1)+I35 -> 23106.528 | S35: =D35*($T$2/100+1)+J35 -> 24226.943 | U35: 27743.138 | V35: =U35-E35 -> 5265.0872 | W35: =U35-F35 -> 4646.9603 | X35: =U35-G35 -> 4683.7971
A36: Верстак 1200 0 0 | D36: ='ВС-О Опора'!F26+'ВС-ПС.1200.0 Полка-стенка'!F25+'ВС-С.1200х22'!F22+'ВС-О Опора'!F26 -> 5215.2221 | G36: 17189.904 | J36: =('Общая комиссия'!I36+'Общая комиссия'!J36+'Общая комиссия'!K36+'Общая комиссия'!L36+'Общая комиссия'!M36+'Общая комиссия'!P36+'Общая комиссия'!Q36)*1.22 -> 11292.999 | M36: =G36-J36 -> 5896.9047 | P36: =M36/D36-1 -> 0.13071016 | S36: =D36*($T$2/100+1)+J36 -> 18072.788
A37: Верстак 1400 0 0 | D37: ='ВС-С.1400х22'!F22+'ВС-ПС.1400.0 Полка-стенка'!F25+'ВС-О Опора'!F26+'ВС-О Опора'!F26 -> 5985.4852 | G37: 21159.397 | J37: =('Общая комиссия'!I37+'Общая комиссия'!J37+'Общая комиссия'!K37+'Общая комиссия'!L37+'Общая комиссия'!M37+'Общая комиссия'!P37+'Общая комиссия'!Q37)*1.22 -> 14465.026 | M37: =G37-J37 -> 6694.371 | P37: =M37/D37-1 -> 0.11843415 | S37: =D37*($T$2/100+1)+J37 -> 22246.157
A38: Стеллаж СТ-СПЭ 10.3 4 п | C38: 1035*360*100 | D38: ='10.3 100 кг'!X30 -> 2894.2678 | G38: 7939.4497 | J38: =('Общая комиссия'!I38+'Общая комиссия'!J38+'Общая комиссия'!K38+'Общая комиссия'!L38+'Общая комиссия'!M38+'Общая комиссия'!P38+'Общая комиссия'!Q38)*1.22 -> 4685.4867 | M38: =G38-J38 -> 3253.9629 | P38: =M38/D38-1 -> 0.12427845 | S38: =D38*($T$2/100+1)+J38 -> 8448.0349
A39: Стеллаж СТ-СПЭ 10.3 6 п | C39: 1035*360*140 | D39: ='10.3 100 кг'!X31 -> 3605.0872 | G39: 10045.249 | J39: =('Общая комиссия'!I39+'Общая комиссия'!J39+'Общая комиссия'!K39+'Общая комиссия'!L39+'Общая комиссия'!M39+'Общая комиссия'!P39+'Общая комиссия'!Q39)*1.22 -> 6013.2394 | M39: =G39-J39 -> 4032.0098 | P39: =M39/D39-1 -> 0.11842229 | S39: =D39*($T$2/100+1)+J39 -> 10699.853
A40: Стеллаж СТ-СПЭ 10.6 4 п | C40: 1035*660*100 | D40: ='10.6 100кг'!T31 -> 5000.8017 | G40: 13392.741 | J40: =('Общая комиссия'!I40+'Общая комиссия'!J40+'Общая комиссия'!K40+'Общая комиссия'!L40+'Общая комиссия'!M40+'Общая комиссия'!P40+'Общая комиссия'!Q40)*1.22 -> 7768.5718 | M40: =G40-J40 -> 5624.1688 | P40: =M40/D40-1 -> 0.12465343 | S40: =D40*($T$2/100+1)+J40 -> 14269.614
...

Sheet Лист1
B1: SKU | C1: Цена + НДС дальн
A2: Аптечка АМУ-1 | B2: 907247263 | C2: =Калькуляция!G2 -> 3150.6549
A3: Ключница К-148 | B3: 629880865 | C3: =Калькуляция!G3 -> 5021.8939
A4: Ключница К-20 | B4: 633898130 | C4: =Калькуляция!G4 -> 1473.6112
A5: Ключница К-40 | B5: 629825193 | C5: =Калькуляция!G5 -> 2970.6978
A6: Ключница К-60 | B6: 629844259 | C6: =Калькуляция!G6 -> 3346.6093
A7: Почтовый ящик ЯП-04 с замками | B7: 632063202 | C7: =Калькуляция!G7 -> 5571.1092
A8: Почтовый ящик ЯП-05 с замками | B8: 631939684 | C8: =Калькуляция!G8 -> 6357.0715
A9: Почтовый ящик ЯП-06 с замками | B9: 631949713 | C9: =Калькуляция!G9 -> 7108.2938
A10: Почтовый ящик ЯП-08 с замками | B10: 631946118 | C10: =Калькуляция!G10 -> 9720.9657
A11: Сейф мебельный СМ-20 | B11: 1667684227 | C11: =Калькуляция!G11 -> 5228.0186
A12: Сейф мебельный СМ-20Э | B12: 1667684137 | C12: =Калькуляция!G12 -> 6070.7009
A13: Сейф мебельный СМ-23 | B13: 1672231528 | C13: =Калькуляция!G13 -> 7876.5144
... A35: ШО-4 | B35: 3541452420 | C35: =Калькуляция!G35 -> 23059.341
A36: Верстак 1200 0 0
A37: Верстак 1400 0 0

Sheet Общая комиссия
A1: Товар | B1: Цена на мп БЛИЖ | C1: Цена на мп СРЕД | D1: Цена на мп ДАЛЬН | E1: Объем Л | F1: Вознаграждение МП процент | G1: Вознаграждение МП руб БЛИЖ | H1: Вознаграждение МП руб СРЕД | I1: Вознаграждение МП руб ДАЛЬН | J1: Тариф отгрузки 1,9 руб/л | K1: Отгрузка в СЦ | L1: Доставка в ПВЗ | M1: Обработка возврата | N1: логистика + обратная ближ | O1: логистика + обратная сред | P1: логистика + обратная дальн | Q1: Эквайринг 1,5%
A2: АМУ-1 | B2: =Калькуляция!E2 -> 2620.3758 | C2: =Калькуляция!F2 -> 2859.3716 | D2: =Калькуляция!G2 -> 3150.6549 | E2: 23 | F2: 0.44 | G2: =B2*F2 -> 1152.9653 | H2: =C2*F2 -> 1258.1235 | I2: =D2*F2 -> 1386.2882 | J2: =1.9*E2 -> 43.7 | K2: 20 | L2: 25 | M2: 15 | N2: ='Тарифы логистика 20-25л'!D11*1.15 -> 295.55 | O2: ='Тарифы логистика 20-25л'!D21*1.15 -> 386.4 | P2: ='Тарифы логистика 20-25л'!D30*1.15 -> 630.2 | Q2: =B2*0.01 -> 26.203758
A3: К148 | B3: =Калькуляция!E3 -> 5069.8174 | C3: =Калькуляция!F3 -> 5175.958 | D3: =Калькуляция!G3 -> 5021.8939 | E3: 13 | F3: 0.43 | G3: =B3*F3 -> 2180.0215 | H3: =C3*F3 -> 2225.662 | I3: =D3*F3 -> 2159.4144 | J3: =1.9*E3 -> 24.7 | K3: 20 | L3: 25 | M3: 15 | N3: ='Тарифы логистика 13-14л '!D12*1.15 -> 211.6 | O3: ='Тарифы логистика 13-14л '!D21*1.15 -> 253 | P3: ='Тарифы логистика 13-14л '!D30*1.15 -> 410.55 | Q3: =B3*0.01 -> 50.698174
A4: К20 | B4: =Калькуляция!E4 -> 1330.7173 | C4: =Калькуляция!F4 -> 1422.1162 | D4: =Калькуляция!G4 -> 1473.6112 | E4: 3 | F4: 0.43 | G4: =B4*F4 -> 572.20844 | H4: =C4*F4 -> 611.50996 | I4: =D4*F4 -> 633.65283 | J4: =1.9*E4 -> 5.7 | K4: 20 | L4: 25 | M4: 15 | N4: ='Тарифы логистика 3-4л'!D13*1.15 -> 117.3 | O4: ='Тарифы логистика 3-4л'!D22*1.15 -> 152.95 | P4: ='Тарифы логистика 3-4л'!D31*1.15 -> 236.9 | Q4: =B4*0.01 -> 13.307173
A5: К40 | B5: =Калькуляция!E5 -> 2790.7106 | C5: =Калькуляция!F5 -> 2896.8512 | D5: =Калькуляция!G5 -> 2970.6978 | E5: 13 | F5: 0.43 | G5: =B5*F5 -> 1200.0056 | H5: =C5*F5 -> 1245.646 | I5: =D5*F5 -> 1277.4001 | J5: =1.9*E5 -> 24.7 | K5: 20 | L5: 25 | M5: 15 | N5: 211.6 | O5: 253 | P5: 410.55 | Q5: =B5*0.01 -> 27.907106
A6: К60 | B6: =Калькуляция!E6 -> 3196.5966 | C6: =Калькуляция!F6 -> 3287.9955 | D6: =Калькуляция!G6 -> 3346.6093 | E6: 14 | F6: 0.43 | G6: =B6*F6 -> 1374.5366 | H6: =C6*F6 -> 1413.8381 | I6: =D6*F6 -> 1439.042 | J6: =1.9*E6 -> 26.6 | K6: 20 | L6: 25 | M6: 15 | N6: ='Тарифы логистика 14-15л'!D12*1.15 -> 221.95 | O6: ='Тарифы логистика 14-15л'!D21*1.15 -> 257.6 | P6: ='Тарифы логистика 14-15л'!D30*1.15 -> 425.5 | Q6: =B6*0.01 -> 31.965966
A7: Почтовый ящик ЯП-4 | B7: =Калькуляция!E7 -> 4755.0731 | C7: =Калькуляция!F7 -> 5037.7341 | D7: =Калькуляция!G7 -> 5571.1092 | E7: 38 | F7: 0.45 | G7: =B7*F7 -> 2139.7829 | H7: =C7*F7 -> 2266.9803 | I7: =D7*F7 -> 2506.9992 | J7: =1.9*E7 -> 72.2 | K7: 20 | L7: 25 | M7: 15 | N7: 479.55 | O7: 584.2 | P7: 1010.85 | Q7: =B7*0.01 -> 47.550731
A8: Почтовый ящик ЯП-5 | B8: =Калькуляция!E8 -> 5538.2857 | C8: =Калькуляция!F8 -> 5814.7344 | D8: =Калькуляция!G8 -> 6357.0715 | E8: 45 | F8: 0.45 | G8: =B8*F8 -> 2492.2285 | H8: =C8*F8 -> 2616.6305 | I8: =D8*F8 -> 2860.6822 | J8: =1.9*E8 -> 85.5 | K8: 20 | L8: 25 | M8: 15 | N8: ='Тарифы логистика 40-45л'!D12*1.15 -> 549.7 | O8: ='Тарифы логистика 40-45л'!D21*1.15 -> 652.05 | P8: ='Тарифы логистика 40-45л'!D30*1.15 -> 1114.35 | Q8: =B8*0.01 -> 55.382857
A9: Почтовый ящик ЯП-6 | B9: =Калькуляция!E9 -> 6006.4496 | C9: =Калькуляция!F9 -> 6369.871 | D9: =Калькуляция!G9 -> 7108.2938 | E9: 50 | F9: 0.45 | G9: =B9*F9 -> 2702.9023 | H9: =C9*F9 -> 2866.4419 | I9: =D9*F9 -> 3198.7322 | J9: =1.9*E9 -> 95 | K9: 20 | L9: 25 | M9: 15 | N9: ='Тарифы логистика 50-60л'!D12*1.15 -> 654.35 | O9: ='Тарифы логистика 50-60л'!D21*1.15 -> 788.9 | P9: ='Тарифы логистика 50-60л'!D30*1.15 -> 1354.7 | Q9: =B9*0.01 -> 60.064496
A10: Почтовый ящик ЯП-8 | B10: =Калькуляция!E10 -> 7836.3059 | C10: =Калькуляция!F10 -> 8561.5279 | D10: =Калькуляция!G10 -> 9720.9657 | E10: 72 | F10: 0.45 | G10: =B10*F10 -> 3526.3376 | H10: =C10*F10 -> 3852.6876 | I10: =D10*F10 -> 4374.4345 | J10: =1.9*E10 -> 136.8 | K10: 20 | L10: 25 | M10: 15 | N10: ='Тарифы логистика 70-80л'!D12 -> 732 | O10: ='Тарифы логистика 70-80л'!D21*1.15 -> 1000.5 | P10: ='Тарифы логистика 70-80л'!D30*1.15 -> 1829.65 | Q10: =B10*0.01 -> 78.363059
A11: СМ 20 | B11: =Калькуляция!E11 -> 5324.119 | C11: =Калькуляция!F11 -> 5409.0258 | D11: =Калькуляция!G11 -> 5228.0186 | E11: 14 | F11: 0.4 | G11: =B11*F11 -> 2129.6476 | H11: =C11*F11 -> 2163.6103 | I11: =D11*F11 -> 2091.2074 | J11: =1.9*E11 -> 26.6 | K11: 20 | L11: 25 | M11: 15 | N11: 221.95 | O11: 257.6 | P11: 425.5 | Q11: =B11*0.01 -> 53.24119
A12: СМ 20-Э | B12: =Калькуляция!E12 -> 6260.4327 | C12: =Калькуляция!F12 -> 6345.3395 | D12: =Калькуляция!G12 -> 6070.7009 | E12: 14 | F12: 0.4 | G12: =B12*F12 -> 2504.1731 | H12: =C12*F12 -> 2538.1358 | I12: =D12*F12 -> 2428.2804 | J12: =1.9*E12 -> 26.6 | K12: 20 | L12: 25 | M12: 15 | N12: 221.95 | O12: 257.6 | P12: 425.5 | Q12: =B12*0.01 -> 62.604327
A13: СМ 23 | B13: =Калькуляция!E13 -> 7486.2973 | C13: =Калькуляция!F13 -> 7735.5399 | D13: =Калькуляция!G13 -> 7876.5144 | E13: 35 | F13: 0.4 | G13: =B13*F13 -> 2994.5189 | H13: =C13*F13 -> 3094.216 | I13: =D13*F13 -> 3150.6058 | J13: =1.9*E13 -> 66.5 | K13: 20 | L13: 25 | M13: 15 | N13: ='Тарифы логистика 35-40л'!D12*1.15 -> 479.55 | O13: ='Тарифы логистика 35-40л'!D21*1.15 -> 584.2 | P13: ='Тарифы логистика 35-40л'!D30*1.15 -> 1010.85 | Q13: =B13*0.01 -> 74.862973
A14: СМ 23-Э | B14: =Калькуляция!E14 -> 8274.1354 | C14: =Калькуляция!F14 -> 8460.3826 | D14: =Калькуляция!G14 -> 8400.691 | E14: 34 | F14: 0.4 | G14: =B14*F14 -> 3309.6542 | H14: =C14*F14 -> 3384.1531 | I14: =D14*F14 -> 3360.2764 | J14: =1.9*E14 -> 64.6 | K14: 20 | L14: 25 | M14: 15 | N14: ='Тарифы логистика 30-35л'!D12*1.15 -> 428.95 | O14: ='Тарифы логистика 30-35л'!D21*1.15 -> 507.15 | P14: ='Тарифы логистика 30-35л'!D30*1.15 -> 874 | Q14: =B14*0.01 -> 82.741354
A15: СМ 25 | B15: =Калькуляция!E15 -> 6103.6318 | C15: =Калькуляция!F15 -> 6320.0072 | D15: =Калькуляция!G15 -> 6210.5943 | E15: 24 | F15: 0.4 | G15: =B15*F15 -> 2441.4527 | H15: =C15*F15 -> 2528.0029 | I15: =D15*F15 -> 2484.2377 | J15: =1.9*E15 -> 45.6 | K15: 20 | L15: 25 | M15: 15 | N15: 295.55 | O15: 386.4 | P15: 630.2 | Q15: =B15*0.01 -> 61.036318
A16: СМ 25-Э | B16: =Калькуляция!E16 -> 7112.7525 | C16: =Калькуляция!F16 -> 7329.1279 | D16: =Калькуляция!G16 -> 7118.8029 | E16: 24 | F16: 0.4 | G16: =B16*F16 -> 2845.101 | H16: =C16*F16 -> 2931.6512 | I16: =D16*F16 -> 2847.5212 | J16: =1.9*E16 -> 45.6 | K16: 20 | L16: 25 | M16: 15 | N16: 295.55 | O16: 386.4 | P16: 630.2 | Q16: =B16*0.01 -> 71.127525
A17: СМ 30 | B17: =Калькуляция!E17 -> 7465.4968 | C17: =Калькуляция!F17 -> 7714.7394 | D17: =Калькуляция!G17 -> 7857.7939 | E17: 37 | F17: 0.4 | G17: =B17*F17 -> 2986.1987 | H17: =C17*F17 -> 3085.8957 | I17: =D17*F17 -> 3143.1176 | J17: =1.9*E17 -> 70.3 | K17: 20 | L17: 25 | M17: 15 | N17: ='Тарифы логистика 35-40л'!D12*1.15 -> 479.55 | O17: ='Тарифы логистика 35-40л'!D21*1.15 -> 584.2 | P17: ='Тарифы логистика 35-40л'!D30*1.15 -> 1010.85 | Q17: =B17*0.01 -> 74.654968
A18: СМ 30-Э | B18: =Калькуляция!E18 -> 8767.4741 | C18: =Калькуляция!F18 -> 9016.7167 | D18: =Калькуляция!G18 -> 9029.5735 | E18: 37 | F18: 0.4 | G18: =B18*F18 -> 3506.9896 | H18: =C18*F18 -> 3606.6867 | I18: =D18*F18 -> 3611.8294 | J18: =1.9*E18 -> 70.3 | K18: 20 | L18: 25 | M18: 15 | N18: 479.55 | O18: 584.2 | P18: 1010.85 | Q18: =B18*0.01 -> 87.674741
A19: СМ 50 | B19: =Калькуляция!E19 -> 9500.6294 | C19: =Калькуляция!F19 -> 9821.0842 | D19: =Калькуляция!G19 -> 10051.774 | E19: 59 | F19: 0.4 | G19: =B19*F19 -> 3800.2518 | H19: =C19*F19 -> 3928.4337 | I19: =D19*F19 -> 4020.7095 | J19: =1.9*E19 -> 112.1 | K19: 20 | L19: 25 | M19: 15 | N19: 654.35 | O19: 788.9 | P19: 1354.7 | Q19: =B19*0.01 -> 95.006294
A20: СМ 50-Э | B20: =Калькуляция!E20 -> 10543.567 | C20: =Калькуляция!F20 -> 10864.022 | D20: =Калькуляция!G20 -> 10990.418 | E20: 59 | F20: 0.4 | G20: =B20*F20 -> 4217.427 | H20: =C20*F20 -> 4345.6089 | I20: =D20*F20 -> 4396.1672 | J20: =1.9*E20 -> 112.1 | K20: 20 | L20: 25 | M20: 15 | N20: 654.35 | O20: 788.9 | P20: 1354.7 | Q20: =B20*0.01 -> 105.43567
A21: Стеллаж металлический200*100*40 4п | B21: =Калькуляция!E21 -> 7814.1939 | C21: =Калькуляция!F21 -> 8027.5475 | D21: =Калькуляция!G21 -> 8092.1113 | E21: 44 | F21: 0.34 | G21: =B21*F21 -> 2656.8259 | H21: =C21*F21 -> 2729.3662 | I21: =D21*F21 -> 2751.3178 | J21: =1.9*E21 -> 83.6 | K21: 20 | L21: 25 | M21: 15 | N21: 549.7 | O21: 652.05 | P21: 1114.35 | Q21: =B21*0.01 -> 78.141939
A22: Стеллаж металлический200*100*50 4п | B22: =Калькуляция!E23 -> 9768.511 | C22: =Калькуляция!F22 -> 8996.8845 | D22: =Калькуляция!G22 -> 9158.6903 | E22: 55 | F22: 0.34 | G22: =B22*F22 -> 3321.2937 | H22: =C22*F22 -> 3058.9407 | I22: =D22*F22 -> 3113.9547 | J22: =1.9*E22 -> 104.5 | K22: 20 | L22: 25 | M22: 15 | N22: 654.35 | O22: 788.9 | P22: 1354.7 | Q22: =B22*0.01 -> 97.68511
A23: Стеллаж металлический200*100*40 6п | B23: =Калькуляция!E22 -> 9152.8146 | C23: =Калькуляция!F23 -> 10533.338 | D23: =Калькуляция!G23 -> 10813.345 | E23: 65 | F23: 0.34 | G23: =B23*F23 -> 3111.957 | H23: =C23*F23 -> 3581.3349 | I23: =D23*F23 -> 3676.5371 | J23: =1.9*E23 -> 123.5 | K23: 20 | L23: 25 | M23: 15 | N23: 756.7 | O23: 914.25 | P23: 1624.95 | Q23: =B23*0.01 -> 91.528146
A24: ШБС 01-МИНИ | B24: =Калькуляция!E24 -> 9149.4402 | C24: =Калькуляция!F24 -> 9524.6735 | D24: =Калькуляция!G24 -> 10095.599 | E24: 64 | F24: 0.4 | G24: =B24*F24 -> 3659.7761 | H24: =C24*F24 -> 3809.8694 | I24: =D24*F24 -> 4038.2395 | J24: =1.9*E24 -> 121.6 | K24: 20 | L24: 25 | M24: 15 | N24: ='Тарифы логистика 60-70л'!D12*1.15 -> 756.7 | O24: ='Тарифы логистика 60-70л'!D21*1.15 -> 914.25 | P24: ='Тарифы логистика 60-70л'!D30*1.15 -> 1624.95 | Q24: =B24*0.01 -> 91.494402
